Internal Server Error: /terrain/userFoundSign/90115385/80/
Traceback (most recent call last):
  File "F:\proj\terrainParkour\env\lib\site-packages\django\core\handlers\exception.py", line 41, in inner
    response = get_response(request)
  File "F:\proj\terrainParkour\env\lib\site-packages\django\core\handlers\base.py", line 187, in _get_response
    response = self.process_exception_by_middleware(e, request)
  File "F:\proj\terrainParkour\env\lib\site-packages\django\core\handlers\base.py", line 185, in _get_response
    response = wrapped_callback(request, *callback_args, **callback_kwargs)
  File "F:\proj\terrainParkour\terrain\controllers.py", line 21, in inner
    return func(request, *kwgs)
  File "F:\proj\terrainParkour\terrain\controllers.py", line 51, in userFoundSign
    assert False
AssertionError
"GET /terrain/userFoundSign/90115385/80/?secret=fw398hfhfdjHEFhjefhFMFfbeF88dfhDjheff3 HTTP/1.1" 200 0
Internal Server Error: /terrain/userFoundSign/90115385/80/
Traceback (most recent call last):
  File "F:\proj\terrainParkour\env\lib\site-packages\django\core\handlers\exception.py", line 41, in inner
    response = get_response(request)
  File "F:\proj\terrainParkour\env\lib\site-packages\django\core\handlers\base.py", line 187, in _get_response
    response = self.process_exception_by_middleware(e, request)
  File "F:\proj\terrainParkour\env\lib\site-packages\django\core\handlers\base.py", line 185, in _get_response
    response = wrapped_callback(request, *callback_args, **callback_kwargs)
  File "F:\proj\terrainParkour\terrain\controllers.py", line 21, in inner
    return func(request, *kwgs)
  File "F:\proj\terrainParkour\terrain\controllers.py", line 51, in userFoundSign
    assert False
AssertionError
"GET /terrain/userFoundSign/90115385/80/?secret=fw398hfhfdjHEFhjefhFMFfbeF88dfhDjheff3 HTTP/1.1" 200 0
